---
title: "JavaScriptのエラーと友達になる方法"
emoji: "🦁"
type: "tech" # tech: 技術記事 / idea: アイデア
topics: ["javascript", "error"]
published: false
---
## はじめに
プログラミングの世界にも当てはまります。アプリケーション作りに、バグやその他の問題の発生はつきもの。JavaScriptでエラーが発生するのは、何も不思議なことではありません。
このような問題を、ユーザーに迷惑をかける前に、いかに解決できるか。これこそが、ソフトウェア製品の成功を左右します。

JavaScriptでWebフロントエンドを開発していると、一度はデータ型でエラーを発生したことがあるのではないでしょうか。undefined や null の扱いでミスを発生するのはよくあることでしょう。

この記事では、JavaScript のエラーについて解説した後、エラーの発生箇所を特定する方法や解決する手法を共有していきます。
実務での運用で効率的にエラーを処理するため Tips もあります。

## そもそもエラーとはなんだろう
Webアプリケーション開発におけるエラーとは、プログラムが正常に動作していない状況のことです。

具体的な例として、
- 存在しないファイルを読み込もうする: `Module not found: Error: Can't resolve ～`
- ネットワークに接続されていない状況でWebサイトにアクセスしする : `net::ERR_INTERNET_DISCONNECTED`

上記の場合だと、プログラムが正常に指示された動作を行うことができない状況です。

このような状況に遭遇するとプログラムは開発者に対しエラーを投げ、「そのプログラムだと問題が発生する」と伝えます。
エラーが発生した原因の情報が収集され、表示してくれるのです。

ですが、WebアプリケーションのユーザーがWebb開発がよく見るようなエラーを読むことがないように、対処するのは大切でしょう。
わかりやすいメッセージとして「ページが見つかりませんでした」などが表示します。

具体例として、
![スクリーンショット 2022-11-05 21 02 39](https://user-images.githubusercontent.com/70939128/200119038-80a5b044-d1ef-4efe-94c6-9ec9b6b7fad5.png)

そして、プログラミング言語である JavaScript のエラーとは、エラーが発生した時に表示されるオブジェクトのことです。
そのオブジェクトには、以下の情報があります。
- エラーの種類
- エラーの原因（ステートメント/statement）
- スタックトレースに関する情報

`extends` を使用して、エラーを拡張させることもできます。これによって、プログラミングの問題を調査する時に表示される情報量を増やすことができます。


### エラーのプロパティ(インスタンスプロパティ)について
JavaScriptのより詳細を解説していきます。
エラーは主に3つから成り立っています。
- Message: 人間が読めるエラーの簡潔な説明
- Name: エラーの種類の名称で初期値は "Error"
- Stack: エラーは発生するまでに呼び出しされたメソッドのスタックトレース

#### スタックトレースとはなんだろう
スタックトレースとは、例外や警告などのイベントが発生したときに、直前にプログラムが実行していたメソッドを一覧で示したものです。

スタックトレースは主に３つから成り立っています。
  - 問題が発生する前の最後のステップ
  - エラーの型とメッセージ
  - ファイルのパス, 行番号、カラム数

具体例として、
```sh
$ node demo.js

/Users/jp-knj/Desktop/demo.js:10
  notDefined();
  ^
RerefenceError: notDefined is not defined 
    at thirdFunction (/Users/jp-knj/Desktop/demo.js:10:3)
    at secondFunction (/Users/jp-knj/Desktop/demo.js:6:3)
    at firstFunction (/Users/jp-knj/Desktop/demo.js:2:3)
    // 以下 省略
```


エラー名とメッセージとして `RerefenceError: notDefined is not defined` が表示されます。
その後に呼び出されたメソッドの一覧が表示されます。 各メソッド呼び出しには、ファイルのパス、、行番号、カラム数を確認できます。
上記のスタックトレースをより詳細に解説すると
```shell
at thirdFunction              // 呼び出された各メソッド
/Users/jp-knj/Desktop/demo.js // ファイルのパス
~/demo.js:10:3                // ファイル名、行番号、カラム数 
```
表示された情報を元に `code jump` して、どのコードがエラーの原因であるかを特定するのができるのです。

このメソッドは、処理の順序を反映するかたちで表示されます。これにより、例外が発生した箇所と、それがどのように伝搬していったのかを確認できるのです。

例外の `catch` を実装すれば、例外がスタックを伝搬しプログラムをクラッシュさせてしまうことはありません。 しかし、致命的なエラーをそのままにし、意図的にプログラムをクラッシュさせるケースも考えられます。

https://developer.mozilla.org/ja/docs/Web/JavaScript/Reference/Global_Objects/Error/Stack

### エラーと例外の大事な違いについて
私自身、エラーと例外との違いを曖昧にしていた開発者です。ですが、大事な違いがありますので理解しておきましょう。
- エラーとは、プログラムが正常に動作していない状況のこと
- 例外とは、投げられたエラーオブジェクトのこと

具体的な例として、
```javascript
const demoError = TypeError('Hello', "someFile.js", 10)

throw demoError 
```

`demoErrorrオブジェクト`が例外です。

業務で使用する場合は、糖衣構文で使っていることが多いのではないでしょうか
```javascript
throw TypeError('Hello', "someFile.js", 10)
```
https://developer.mozilla.org/ja/docs/Web/JavaScript/Reference/Global_Objects/TypeError

## JavaScript にはどんなエラーがあるのだろう

JavaScriptには、定義されたさまざまなエラーのタイプがあります。 これは、Webアプリケーションで明示的にエラーの処理を行い限り、JavaScriptランタイムによって自動的に選択、定義されます。

JavaScriptで主なエラーのタイプ、各タイプはいつ、どのような理由で発生するのかを解説していきます。

#### TypeError
このエラーのタイプはよく開発者も多いのではないでしょうか。
変数や引数の型が想定された型でないことが検出されたときに表示されます。

具体例として
```javascript
TypeError: Object doesn't support property or method {x} (Edge)
TypeError: "x" is not a function
```
関数でないものを、関数呼び出ししようとしたときに発生するエラーです。
特定の関数が定義されていることを想定しているが、定義されていないときも発生するでしょう。
![スクリーンショット 2022-11-05 23 29 10](https://user-images.githubusercontent.com/70939128/200124762-15c0bc5c-286e-4a64-8cb1-1686f510a2d9.png)

https://developer.mozilla.org/ja/docs/Web/JavaScript/Reference/Errors/Not_a_function

#### ReferenceError
コード内の変数の参照に問題があるときに表示されます。
変数を使用する前に値を定義するのを忘れたか、またはコードでアクセスできない変数を使用しようとしている可能性があります。
いずれにしても、スタックトレースを確認することで、問題のある変数の参照を見つけ、修正にあたることができます。

具体例として
```javascript
ReferenceError: "x" is not defined
```
![スクリーンショット 2022-11-05 23 26 46](https://user-images.githubusercontent.com/70939128/200124760-31164dd4-b345-4c40-a336-40d7128c0beb.png)
変数は現在の実行コンテキストで利用可能である必要があります。関数の中で定義された変数は、その関数のスコープ内でしか定義されていないので、関数の外のどこからもアクセスできません。

#### RangeError
変数に有効な値の範囲外にある値が設定されたときに表示されます。
関数に引数として値を渡すときに発生し、与えられた値が関数のパラメータの範囲内にないことを示します。正しい値を渡すためには、引数に取り得る値の範囲を知る必要があるため、サードパーティのライブラリのドキュメントが不十分な場合、このエラーの解決には手間がかかる可能性があります。

```javascript
RangeError: Invalid array length
```
![スクリーンショット 2022-11-05 22 58 46](https://user-images.githubusercontent.com/70939128/200124463-99302564-8110-4fe7-bff3-4a0e13fa15b1.png)

a.length(配列の要素の数)を負の数にして、対応している値を超えてしまった

Arrayコンストラクタで不正な長さの配列を作成しようとした
toExponential()、toPrecision()、toFixed()などのメソッドに不正な値を渡した

#### SyntaxError
修正するのが最も簡単なものエラーです。JavaScriptはスクリプト言語ですので、スクリプトにあるエラーがあると、実行時に、このようなエラーが返されます。
コンパイル言語では、このようなエラーはコンパイル時に発見されます。したがって、エラーが解決されるまで、アプリケーションのバイナリを生成することはないでしょう。

```javascript
SyntaxError: expected expression, got "x"
```
![スクリーンショット 2022-11-05 23 27 18](https://user-images.githubusercontent.com/70939128/200124968-7e459f02-4483-496e-a51e-df0f74d22f56.png)
eslint を使って、発見しましょう


#### InternalError
InternalErrorは、JavaScriptのランタイムエンジンで例外が発生したときに表示されます。
これはコードの問題を意味することも、そうでないこともあります。
```javascript
RangeError: Maximum call stack size exceeded
```

具体例として、関数の呼び出しが多すぎるときに表示されます。
![スクリーンショット 2022-11-05 23 27 40](https://user-images.githubusercontent.com/70939128/200124933-38e2bf52-fb02-45f2-9158-3912a6f2e6e7.png)

JavaScriptエンジンにとって大きすぎるエンティティがコード内に存在する（例：switch文のcaseの分岐が多すぎる、配列初期化子が大きすぎる、再帰が多すぎる）

JavaScriptエンジンの作業負荷が急激に上昇してしまうのを避けましょう。

#### URIError
URIErrorは、decodeURIComponentのようなグローバルなURI処理関数が間違った方法で使用されたときに表示されます。
メソッド呼び出しに渡されたパラメータがURI標準に準拠しておらず、メソッドによって適切にパースされなかったことを意味します。
```javascript
URIError: URI malformed
```

![スクリーンショット 2022-11-05 23 28 10](https://user-images.githubusercontent.com/70939128/200124913-007b30d7-74dc-4a43-ae5e-2cf901eebcd4.png)

引数に問題がないかを調べるだけで対処できるので簡単です。

#### EvalError
EvalErrorは、eval()関数の呼び出しで問題が発生したことを意味します。eval()関数は、文字列に格納されたJavaScriptコードを実行するのに使用されます。しかし、eval()関数の使用はセキュリティ上の問題から推奨されておらず、現在のECMAScriptの仕様ではEvalErrorクラスは返されないため、このエラーはあくまでも古いJavaScriptコードとの後方互換性を維持するために存在しています。

古いバージョンのJavaScriptで作業していると、このエラーに遭遇する可能性があります。いずれにせよ、eval()関数の呼び出しで実行されたコードに例外がないかどうか調査するのが得策です。


### エラーをカスタマイズしよう！

JavaScriptには、デフォルトで、ほとんどの状況を網羅できるだけのエラータイプクラスがあります。しかし、必要であれば、その他にもエラータイプを作成することができます。この柔軟性を支えるのが、JavaScriptがthrowコマンドで文字通り何でも返すことができるという性質です。

技術的に、以下のようなステートメントは完全に有効です。
```javascript
throw 8
throw "An error occurred"
```
しかし、プリミティブ型では、その型や名前、付随するスタックトレースなど、エラーの詳細についてはわかりません。これに対処し、プロセスを標準化するために、Errorクラスがあります。尚、例外を表示する際にプリミティブ型を使用することは推奨されていません。

Errorクラスを拡張して、独自のエラークラスを作成することができます。その基本的な例は以下の通りです。
```javascript
class ValidationError extends Error {
    constructor(message) {
        super(message);
        this.name = "ValidationError";
    }
}
```
これを、次のように使うことができます。
```javascript
throw ValidationError("Property not found: name")
```
そして `instanceofキーワード` と組み合わせます。
```javascript
try {
    validateForm() // code that throws a ValidationError
} catch (e) {
    if (e instanceof ValidationError) {
        // do something
    } else {
        // do something else
    }
}
```

## エラーを特定しよう！
上で説明したエラーは、JavaScriptでよく見られるものですが、いくつかの例を知っておくだけでは十分ではありません。JavaScriptアプリケーションを開発する上で、どのようにエラーを検出し、防止するかを理解しておくことが重要です。そこで、JavaScriptのエラーを処理する方法をご紹介します。

### エラーを「throw」＆「catch」する
ランタイムによって返されたエラーを処理する基礎となる、catch です。他の多くの言語と同様に、JavaScript にはエラーの処理に使える機能がいくつもあります。JavaScriptアプリケーションでのエラー処理について話す前に、それぞれを使ってできることを理解しておきましょう。

#### throw
名前からも明らかなように、throw は JavaScript で例外を投げるのに使用します。

`number`,`string`、`Errorオブジェクト` など、何でも`throw`することができる
しかし、文字列や数値などのプリミティブ型は、エラーに関するデバッグ情報を持たないため、投げるのは得策ではない
```javascript
throw TypeError("Please provide a string") 
```

#### try
コードが例外を投げる可能性があることを示すために使用されます。

```javascript
try {
// error-prone code here
}
```
注意すべき点として、エラーを処理するために、必ず`tryブロック`の後に`catchブロック`を記述します

#### catch
catch は、ブロックをキャッチするのに使用します。つまり、`tryブロック`により捕捉されたエラーを処理する役割を果たします。
```javascript
catch (exception) {
// code to handle the exception here
}
```
そして、 try と catch をあわせて使用すると以下のようになります。
```javascript
try {
// business logic code
} catch (exception) {
// error handling code
}
```
1つのcatchブロックの中でif...else文やswitch-case文を使って、起こりうるすべてのエラーのパターンを処理することができます。
```javascript
try {
    // business logic code
} catch (exception) {
    if (exception instanceof TypeError) {
        // do something
    } else if (exception instanceof RangeError) {
        // do something else
    }
}
```
#### finally
finally は、エラー処理後に実行されるコードブロックの定義に使用します。つまり、try と catch の後に実行されます。

また、finallyブロック は他の2つのブロックの結果に関係なく実行されます。つまり、catchブロック がエラーを完全に処理できない場合や、catchブロック でエラーが発生した場合でも、プログラムがクラッシュする前にインタプリタによりfinallyブロックのコードが実行されます。

tryブロック は、その後に catch か finally どちらかが続かないと有効とは言えません。どちらも存在しないと、インタプリタにより`SyntaxError`が返されます。
したがって、エラー処理を行う際には、`tryブロック` の後に少なくともどちらかのブロックを記述するようにしてください。

### onerror() メソッドでグローバルにエラーを処理する
`onerror()メソッド`は、すべてのHTML要素で発生する可能性のあるエラーを処理するのに使用できます。例えば、imgタグが指定されたURLの画像を見つけられなかった場合、onerrorメソッドを呼び出します。こうすることで、ユーザーによるエラーの処理が可能になります。

通常、imgタグがフォールバックできるように、onerrorで別の画像URLを用意します。JavaScriptでこれを行う方法は次の通りです。
```javascript
const image = document.querySelector("img")
image.onerror = (event) => {
    console.log("Error occurred: " + event)
}
```
この機能を利用して、アプリのグローバルなエラー処理の仕組みを作成することができます。以下が、その具体的な方法です。
```javascript
window.onerror = (event) => {
    console.log("Error occurred: " + event)
}
```
このイベントハンドラを使用すると、コード内にある複数のtry...catchブロックを取り除き、イベント処理と同様にアプリのエラー処理を一元化することができます。「SOLID」（設計指針）の「単一責任の原則」を守るために、複数のエラーハンドラをwindowに紐付けることが可能です。該当するハンドラに到達するまで、インタプリタがハンドラを順に辿っていきます。

#### コールバックでエラーを渡す
直線的な関数では、シンプルにエラー処理が実行されますが、コールバックを用いることで、その手順を複雑化することができます。

次のようなコードを考えてみましょう。
```javascript
const calculateCube = (number, callback) => {
    setTimeout(() => {
        const cube = number * number * number
        callback(cube)
    }, 1000)
}

const callback = result => console.log(result)

calculateCube(4, callback)
```
上記の関数では、処理に時間を取り、コールバックを利用することで後から結果を返すという非同期の仕組みが作られています。

関数呼び出しの際に4ではなく文字列を入力すると、結果としてNaNが返されます。

これに対処する方法が以下の通りです。
```javascript
const calculateCube = (number, callback) => {
    setTimeout(() => {
        if (typeof number !== "number")
            throw new Error("Numeric argument is expected")

        const cube = number * number * number
        callback(cube)
    }, 1000)
}

const callback = result => console.log(result)

try {
    calculateCube(4, callback)
} catch (e) { 
    console.log(e)
}
```
これで理想的には問題が解決するはずです。しかし、関数呼び出しに文字列を渡そうとすると、次のようになります。

関数呼び出し、try-catchブロックを実装しているにもかかわらず、エラーが「uncaught」であると表示されます。タイムアウトによる遅延のため、catchブロックが実行された後にエラーが投げられます。

これは、ネットワーク通話で（予期せぬ遅延が介在し得るため）発生することがあり、このような状況を網羅しながら、アプリを開発する必要があります。

コールバックでエラーを処理する方法は、次の通りです。
```javascript
const calculateCube = (number, callback) => {
    setTimeout(() => {
        if (typeof number !== "number") {
            callback(new TypeError("Numeric argument is expected"))
            return
        }
        const cube = number * number * number
        callback(null, cube)
    }, 2000)
}

const callback = (error, result) => {
    if (error !== null) {
        console.log(error)
        return
    }
    console.log(result)
}

try {
    calculateCube('hey', callback)
} catch (e) {
    console.log(e)
}
```
これで、コンソールの出力は、次のようになります。

これは、エラーが適切に処理されたことを意味します。

#### promise中のエラーの処理
非同期アクティビティの処理にはpromiseが好まれる傾向にあります。promiseには、それがrejectされてもスクリプトが終了することはない、という強みがあります。しかし、promiseのエラーを処理するために、catchブロックを実装する必要があります。理解を深めるために、promiseを使用してcalculateCube()関数を書き換えてみましょう。
```javascript
const delay = ms => new Promise(res => setTimeout(res, ms));

const calculateCube = async (number) => {
    if (typeof number !== "number") 
        throw Error("Numeric argument is expected")
    await delay(5000)
    const cube = number * number * number
    return cube
}

try {
    calculateCube(4).then(r => console.log(r))
} catch (e) {
    console.log(e)
}
```
前のコードにあったtimeoutは、理解しやすいようにdelay関数に分離しました。4の代わりに文字列を入力しようとすると、出力は以下のようになります。

promiseの引数に誤りがある場合のTypeErrorの例
ここでも、他のすべての処理が完了した後にpromiseがエラーを投げることが原因となっています。この問題の解決方法は簡単です。以下のようにpromiseチェーンにcatch()呼び出しを追加するだけでOKです。
```javascript
calculateCube("hey")
    .then(r => console.log(r))
    .catch(e => console.log(e))
```
これで、出力は以下のようになります。

誤った引数を利用したことによるTypeErrorの対処例
promiseを用いたエラー処理がいかに簡単であるかをご理解いただけたはずです。さらに、finally()ブロックとpromise呼び出しを連鎖させ、エラー処理完了後に実行するコードを追加することもできます。

また、従来型のtry-catch-finallyを用いて、promiseのエラーを処理することもできます。その場合のpromise呼び出しは以下のようになります。
```javascript
try {
    let result = await calculateCube("hey")
    console.log(result)
} catch (e) {
    console.log(e)
} finally {
    console.log('Finally executed")
}
```
しかし、これは非同期関数の中でのみ機能します。というわけで、promiseのエラーを処理する最適解は、promise呼び出しに、catchとfinallyを連鎖させることです。

「throw/catch」、「onerror()」、「callback（コールバック）」、「promise」─どれを使うべきか
ここまでで触れてきたとおり、4つの方式があります。状況ごとに使える選択肢は異なります。続いては、選別方法を考えてみましょう。

- throw/catch 
  - ほとんどの状況で、これを使用することになります。catchブロックの中で、起こりうるすべてのエラーに対する処理を実装するようにしてください。また、tryブロックの後にメモリのクリーンアップを行う必要がある場合は、finallyブロックの記述をお忘れなく。

とは言え、try/catchブロックが多すぎると、コードのメンテナンスが難しくなります。そのような場合は、グローバルハンドラやpromiseメソッドでエラーを処理することをおすすめします。

非同期try/catchブロックとpromiseのcatch()のどちらを選択するについてですが、非同期try/catchブロックの方が、コードが直線的になり、デバッグしやすいので、そちらを推奨します。

- onerror()
  - onerror() メソッドは、アプリケーションで多くのエラーを処理する必要があり、 しかも問題の箇所がコードベース全体に散らばっていることが分かっている場合に有用です。Onerror()を使用すると、エラーをアプリケーション内のイベントのように扱うことができます。複数のエラーハンドラを定義して、最初のレンダリング時にアプリのwindowに紐付けることが可能です。

しかし、エラーの範囲が狭い小規模なプロジェクトでは、onerror()メソッドの設定が不必要に難しくなることがありますのでご注意ください。対象のアプリにあまり多くのエラーがないことを確信しているなら、より基本的なthrow/catchを使う方がいいでしょう。

- callback（コールバック）とpromise 
  - コールバックとpromiseのエラー処理は、その設計や構造から異なります。コードを書く前にこの2つのどちらかを選ぶのであれば、promiseを選ぶのが賢明です。

というのも、promiseにはcatch()とfinally()ブロックを連鎖させてエラーを簡単に処理する仕組みが組み込まれています。この方法は、エラーを処理するために引数を定義したり、既存の引数を再利用したりするよりも簡単でクリーンです。

#### Gitリポジトリで変更点を追跡する
コードベース内のミスでエラーが発生することは、ある意味で不可避です。開発中やデバッグ中に、不必要な変更を加えてしまい、それが原因で新たなエラーが発生することすらあります。変更を加えるたびに自動でのテストを実行しておくのが得策です。ただし、これにより分かるのは、問題があるかないかという結果だけです。コードのバックアップを頻繁に取らないと、以前は問題なく機能していたはずの関数やスクリプトを修正することに、多くの時間を取られる可能性もあります。

そこで、Gitです。ちゃんとコミット戦略を立てることで、Gitの履歴をバックアップシステムとして使用し、開発中のコードの変遷を追跡することができます。以前のコミットの確認も簡単です。無駄に手を加えてしまった箇所や特定のバージョンを楽々見つけることができます。

そして、前のコードを復元したり、2つのバージョンを比較したりして、何が悪かったのかを判断することも可能です。GitHub DesktopやGitKrakenのような最新のウェブ開発ツールを使えば、変更点を並べて視覚化し、間違いを素早く突き止めることができます。

ミスを減らすための習慣として、コードに大きな変更を加えるたびにコードレビューを実施することをおすすめします。チームで作業している場合は、プルリクエストを作成し、チームメンバーに徹底的にレビューしてもらうのが鉄則です。あなたがうっかり見落としているエラーが見つかるかもしれません。


## エラーを解決しよう！
エラー解決の効果を最大化するためには、実装の際にいくつかの点に留意したいところです。具体的なヒントを以下にまとめました。 

### 操作上の例外処理に独自のエラータイプを使用する
   記事の前半で独自のエラータイプの作成方法をご紹介しました。これは、アプリケーション固有の状況に合わせてエラー処理のしかたを調整できるようになるためです。一般的な Error クラスではなく、可能な限り独自のエラータイプを使用することをお勧めします。そうすることで、通常よりも多くの情報や背景が確認できるようになります。

さらに、独自のエラータイプでは、呼び出し側の環境におけるエラーの表示方法を調整することができます。つまり、特定の項目を隠したり、エラーに関するもっと詳しい情報を表示したりできます。

エラーの内容を好きなようにフォーマットすることも可能です。エラーの解釈や処理のしかたを細かく制御することができます。

### 例外を放置しない
   上級開発者であっても、コードの奥深くで例外をほったらかしにしてしまう、という初歩的なミスを犯すことがよくあります。

例えば、こんな状況です。実行が任意であるコードがあったとします。もしそれが機能すれば、素晴らしいことです。一方でもし機能しなくても、大した問題はありません。

このような場合、このコードをtryブロックに入れ、空のcatchブロックでその場しのぎをしたくなるかもしれません。しかし、そうすることで、そのコードがあらゆる種類のエラーを引き起こす可能性があります。これは、コードベースが大きくなった時、そして、このようなエラー管理の不備が多い場合、大きなリスクとなります。

例外を処理する上でのベストプラクティスはこうです。すべての例外を処理するレベルを決定し、そこに至るまでに、例外処理にとばすこと。このレベルは、コントローラ（MVCアーキテクチャのアプリの場合）でもミドルウェア（従来のサーバー指向のアプリの場合）でもかまいません。

こうすることで、アプリで発生しているすべてのエラーの場所を把握しながら対処法（たとえ何もしないことを選ぼうとも）を賢く選択できるようになります。

### ログとエラーアラートを一元化する
   エラーの処理における大事な要素として、ログを取ることが挙げられます。エラーのログを一元的に管理しないと、アプリの使用状況に関する貴重な情報を見逃してしまう可能性があります。

アプリのイベントログを確認することで、エラーに関する重要なデータを把握し、素早いデバッグに役立てることができます。アプリに適切なアラートメカニズムを設定しておいて、エラーが発生したときに、それが多くのユーザーに影響を及ぼす前に把握するのが理想です。

デフォルトのロガーを使用するか、好みにあわせてロガーを作成することをお勧めします。ロガーの中には、エラーのレベル (警告、デバッグ、情報など) に応じて処理方法を設定でき、中にはログをすぐにリモートロギングのサーバーに送信するものさえあります。このようにして、アプリケーションのロジックが利用者に対してどのように実行されるかを監視できます。

### ユーザーに対し適切にエラーを通知する
   エラー処理方法を定義する際に、ユーザーを念頭に置く必要があります。

アプリの正常な機能を妨げるすべての問題は、目に見えるかたちで（アラートやエラーメッセージで）確認できるようにしましょう。これにより、ユーザーによる解決策の実施が促せます。操作の再試行やログアウトと再ログインなど、エラーの簡単な解決方法を知っている場合は、アラートに必ず記載しましょう。

日常的な使用に支障をきたさないエラーの場合、アラートは出さずに、後で解決できるように、リモートサーバーで記録することも可能です。

### ミドルウェアの実装（Node.js）
   Node.js環境はサーバーアプリケーションに機能を追加するミドルウェアをサポートしています。この機能を利用して、サーバーのエラー処理用ミドルウェアを作成することができます。

ミドルウェアを使用する最も大きな利点は、すべてのエラーを一箇所で集中的に処理できること。この設定は、テスト用に簡単に有効/無効化できます。

基本的なミドルウェアの作り方を説明します。
```javascript
export const logError = err => {
    console.log("ERROR: " + String(err))
}

export const errorLoggerMiddleware = (err, req, res, next) => {
    logError(err)
    next(err)
}

export const returnErrorMiddleware = (err, req, res, next) => {
    res.status(err.statusCode || 500)
        .send(err.message)
}
```
そして、このミドルウェアをアプリ内で次のように使用することができます。
```javascript
import { errorLoggerMiddleware, returnErrorMiddleware } from "./middleware"

app.use(errorLoggerMiddleware)

app.use(returnErrorMiddleware)
```
これで、ミドルウェアの内部で独自のロジックを定義し、適切にエラーを処理できます。もう、コードベース全体で、個別のエラー処理構造の実装に頭を悩ませる必要はありません。

#### 意図的にアプリを再起動する (Node.js)
   Node.jsアプリがエラーに遭遇した際、必ずしも例外を投げるとは限らず、アプリを終了しようとする場合があります。このようなエラーとして、CPUの大量消費、メモリの肥大化、メモリリークなど、プログラミングのミスに起因する問題が挙げられます。これが発生した場合には、Node.jsのクラスタモードや、PM2のようなツールを使ってアプリをクラッシュさせ、再起動（グレースフル・リスタート）させるのが理想です。これにより、ユーザーの操作によってアプリがクラッシュしてユーザー体験が害されるのを回避できます。

#### 「uncaught」の例外を全て「catch」する (Node.js)
   プログラミングを徹底しようとも、アプリで発生する可能性のあるすべてのエラーをカバーできているとは限りません。したがって、アプリで発生する「捕捉から漏れた」例外をすべてcatchするフォールバック戦略を実装することが肝要です。

その方法をご紹介します。
```javascript
process.on('uncaughtException', error => {
console.log("ERROR: " + String(error))
// other handling mechanisms
})
```
また、発生したエラーが標準的な例外なのか、特別な操作エラーなのかを識別することもできます。その結果に基づいて、プロセスを終了し、再起動することで、予期せぬ動作を回避することが可能です。

#### 未処理の「reject」をすべて「catch」する（Node.js）
   例外をすべてカバーすることができないのと同様に、promiseのrejectをすべて処理しきれない可能性もあります。しかし、例外とは異なり、promiseのrejectはエラーを投げません。

そのため、重要なpromiseがrejectになった場合、それが最終的には、予期せぬ動作につながるリスクがあります。そのため、promiseのrejectを処理するフォールバックの仕組みを実装することが非常に重要です。

その方法が、以下の通りです。
```javascript
const promiseRejectionCallback = error => {
    console.log("PROMISE REJECTED: " + String(error))
}

process.on('unhandledRejection', callback)
```
## さいごに
エラーは自然なものです。場合によっては、ユーザーへの反応として、意図的にエラーを投げる必要があることさえあります。したがって、エラーの構造と種類を理解することは非常に重要です。
さらに、アプリケーションを停止させてしまうエラーを特定し、それを防ぐための知識と道具を用意しておく必要があります。

間違った知識や内容がありましたら、ご指摘ください。