---
title: "JavaScriptのエラーと友達になるために"
emoji: "🦁"
type: "tech" # tech: 技術記事 / idea: アイデア
topics: ["javascript", "エラー", "error", "エラーハンドリング"]
published: false
---
## はじめに
プログラミングの世界にも当てはまります。アプリケーション作りに、バグやその他の問題の発生はつきもの。JavaScriptでエラーが発生するのは、何も不思議なことではありません。
このような問題を、ユーザーに迷惑をかける前に、いかに解決できるか。これこそが、ソフトウェア製品の成功を左右します。

JavaScriptでWebフロントエンドを開発していると、一度はデータ型でエラーを発生したことがあるのではないでしょうか。undefined や null の扱いでミスを発生するのはよくあることでしょう。

この記事では、JavaScript のエラーについて解説した後、エラーの発生箇所を特定する方法や解決する手法を共有していきます。
実務での運用で効率的にエラーを処理するため Tips もあります。

## そもそもエラーとはなんだろう
Webアプリケーション開発におけるエラーとは、プログラムが正常に動作していない状況のことです。

具体的な例として、
- 存在しないファイルを読み込もうする: `Module not found: Error: Can't resolve ～`
- ネットワークに接続されていない状況でWebサイトにアクセスしする : `net::ERR_INTERNET_DISCONNECTED`

上記の場合だと、プログラムが正常に指示された動作を行うことができない状況です。

このような状況に遭遇するとプログラムは開発者に対しエラーを投げ、「そのプログラムだと問題が発生する」と伝えます。
エラーが発生した原因の情報が収集され、表示してくれるのです。

ですが、WebアプリケーションのユーザーがWebb開発がよく見るようなエラーを読むことがないように、対処するのは大切でしょう。
わかりやすいメッセージとして「ページが見つかりませんでした」などが表示します。

具体例として、
![スクリーンショット 2022-11-05 21 02 39](https://user-images.githubusercontent.com/70939128/200119038-80a5b044-d1ef-4efe-94c6-9ec9b6b7fad5.png)

そして、プログラミング言語である JavaScript のエラーとは、エラーが発生した時に表示されるオブジェクトのことです。
そのオブジェクトには、以下の情報があります。
- エラーの種類
- エラーの原因（ステートメント/statement）
- スタックトレースに関する情報

`extends` を使用して、エラーを拡張させることもできます。これによって、プログラミングの問題を調査する時に表示される情報量を増やすことができます。


### エラーのプロパティ(インスタンスプロパティ)について
JavaScriptのより詳細を解説していきます。
エラーは主に3つから成り立っています。
- Message: 人間が読めるエラーの簡潔な説明
- Name: エラーの種類の名称で初期値は "Error"
- Stack: エラーは発生するまでに呼び出しされたメソッドのスタックトレース

#### スタックトレースとはなんだろう
スタックトレースとは、例外や警告などのイベントが発生したときに、直前にプログラムが実行していたメソッドを一覧で示したものです。

スタックトレースは主に３つから成り立っています。
  - 問題が発生する前の最後のステップ
  - エラーの型とメッセージ
  - ファイルのパス, 行番号、カラム数

具体例として、
```sh
$ node demo.js

/Users/jp-knj/Desktop/demo.js:10
  notDefined();
  ^
RerefenceError: notDefined is not defined 
    at thirdFunction (/Users/jp-knj/Desktop/demo.js:10:3)
    at secondFunction (/Users/jp-knj/Desktop/demo.js:6:3)
    at firstFunction (/Users/jp-knj/Desktop/demo.js:2:3)
    // 以下 省略
```


エラー名とメッセージとして `RerefenceError: notDefined is not defined` が表示されます。
その後に呼び出されたメソッドの一覧が表示されます。 各メソッド呼び出しには、ファイルのパス、、行番号、カラム数を確認できます。
上記のスタックトレースをより詳細に解説すると
```shell
at thirdFunction              // 呼び出された各メソッド
/Users/jp-knj/Desktop/demo.js // ファイルのパス
~/demo.js:10:3                // ファイル名、行番号、カラム数 
```
表示された情報を元に `code jump` して、どのコードがエラーの原因であるかを特定するのができるのです。

このメソッドは、処理の順序を反映するかたちで表示されます。これにより、例外が発生した箇所と、それがどのように伝搬していったのかを確認できるのです。

例外の `catch` を実装すれば、例外がスタックを伝搬しプログラムをクラッシュさせてしまうことはありません。 しかし、致命的なエラーをそのままにし、意図的にプログラムをクラッシュさせるケースも考えられます。

https://developer.mozilla.org/ja/docs/Web/JavaScript/Reference/Global_Objects/Error/Stack

### エラーと例外の大事な違いについて
私自身、エラーと例外との違いを曖昧にしていた開発者です。ですが、大事な違いがありますので理解しておきましょう。
- エラーとは、プログラムが正常に動作していない状況のこと
- 例外とは、投げられたエラーオブジェクトのこと

具体的な例として、
```javascript
const demoError = TypeError('Hello', "someFile.js", 10)

throw demoError 
```

`demoErrorrオブジェクト`が例外です。

業務で使用する場合は、糖衣構文で使っていることが多いのではないでしょうか
```javascript
throw TypeError('Hello', "someFile.js", 10)
```
https://developer.mozilla.org/ja/docs/Web/JavaScript/Reference/Global_Objects/TypeError

## JavaScript にはどんなエラーがあるのだろう

JavaScriptには、定義されたさまざまなエラーのタイプがあります。 これは、Webアプリケーションで明示的にエラーの処理を行い限り、JavaScriptランタイムによって自動的に選択、定義されます。

JavaScriptで主なエラーのタイプ、各タイプはいつ、どのような理由で発生するのかを解説していきます。

#### TypeError
このエラーのタイプはよく開発者も多いのではないでしょうか。
変数や引数の型が想定された型でないことが検出されたときに表示されます。

具体例として
```javascript
TypeError: Object doesn't support property or method {x} (Edge)
TypeError: "x" is not a function
```
関数でないものを、関数呼び出ししようとしたときに発生するエラーです。
特定の関数が定義されていることを想定しているが、定義されていないときも発生するでしょう。
![スクリーンショット 2022-11-05 23 29 10](https://user-images.githubusercontent.com/70939128/200124762-15c0bc5c-286e-4a64-8cb1-1686f510a2d9.png)

https://developer.mozilla.org/ja/docs/Web/JavaScript/Reference/Errors/Not_a_function

#### ReferenceError
コード内の変数の参照に問題があるときに表示されます。
変数を使用する前に値を定義するのを忘れたか、またはコードでアクセスできない変数を使用しようとしている可能性があります。
いずれにしても、スタックトレースを確認することで、問題のある変数の参照を見つけ、修正にあたることができます。

具体例として
```javascript
ReferenceError: "x" is not defined
```
![スクリーンショット 2022-11-05 23 26 46](https://user-images.githubusercontent.com/70939128/200124760-31164dd4-b345-4c40-a336-40d7128c0beb.png)
変数は現在の実行コンテキストで利用可能である必要があります。関数の中で定義された変数は、その関数のスコープ内でしか定義されていないので、関数の外のどこからもアクセスできません。

#### RangeError
変数に有効な値の範囲外にある値が設定されたときに表示されます。
関数に引数として値を渡すときに発生し、与えられた値が関数のパラメータの範囲内にないことを示します。正しい値を渡すためには、引数に取り得る値の範囲を知る必要があるため、サードパーティのライブラリのドキュメントが不十分な場合、このエラーの解決には手間がかかる可能性があります。

```javascript
RangeError: Invalid array length
```
![スクリーンショット 2022-11-05 22 58 46](https://user-images.githubusercontent.com/70939128/200124463-99302564-8110-4fe7-bff3-4a0e13fa15b1.png)

a.length(配列の要素の数)を負の数にして、対応している値を超えてしまった

Arrayコンストラクタで不正な長さの配列を作成しようとした
toExponential()、toPrecision()、toFixed()などのメソッドに不正な値を渡した

#### SyntaxError
修正するのが最も簡単なものエラーです。JavaScriptはスクリプト言語ですので、スクリプトにあるエラーがあると、実行時に、このようなエラーが返されます。
コンパイル言語では、このようなエラーはコンパイル時に発見されます。したがって、エラーが解決されるまで、アプリケーションのバイナリを生成することはないでしょう。

```javascript
SyntaxError: expected expression, got "x"
```
![スクリーンショット 2022-11-05 23 27 18](https://user-images.githubusercontent.com/70939128/200124968-7e459f02-4483-496e-a51e-df0f74d22f56.png)
eslint を使って、発見しましょう


#### InternalError
InternalErrorは、JavaScriptのランタイムエンジンで例外が発生したときに表示されます。
これはコードの問題を意味することも、そうでないこともあります。
```javascript
RangeError: Maximum call stack size exceeded
```

具体例として、関数の呼び出しが多すぎるときに表示されます。
![スクリーンショット 2022-11-05 23 27 40](https://user-images.githubusercontent.com/70939128/200124933-38e2bf52-fb02-45f2-9158-3912a6f2e6e7.png)

JavaScriptエンジンにとって大きすぎるエンティティがコード内に存在する（例：switch文のcaseの分岐が多すぎる、配列初期化子が大きすぎる、再帰が多すぎる）

JavaScriptエンジンの作業負荷が急激に上昇してしまうのを避けましょう。

#### URIError
URIErrorは、decodeURIComponentのようなグローバルなURI処理関数が間違った方法で使用されたときに表示されます。
メソッド呼び出しに渡されたパラメータがURI標準に準拠しておらず、メソッドによって適切にパースされなかったことを意味します。
```javascript
URIError: URI malformed
```

![スクリーンショット 2022-11-05 23 28 10](https://user-images.githubusercontent.com/70939128/200124913-007b30d7-74dc-4a43-ae5e-2cf901eebcd4.png)

引数に問題がないかを調べるだけで対処できるので簡単です。

#### EvalError
後方互換性のために存在しています。
現在のECMAScriptの仕様ではEvalErrorクラスは返されないため、あくまでも古いバージョンで作業すると、直面するかもしれないエラーになります。
`eval()メソッド`の呼び出しで実行されたコードに例外がないかどうか調査するために頭の片隅に置いておく程度でよいかもしれません。

https://developer.mozilla.org/ja/docs/Web/JavaScript/Reference/Global_Objects/EvalError

### エラーをカスタマイズしよう！

JavaScriptには、デフォルトで、ほとんどの状況を網羅できるだけのエラータイプクラスがあります。しかし、必要であれば、その他にもエラータイプを作成することができます。この柔軟性を支えるのが、JavaScriptがthrowコマンドで文字通り何でも返すことができるという性質です。

技術的に、以下のようなステートメントは完全に有効です。
```javascript
throw 8
throw "An error occurred"
```
しかし、プリミティブ型では、その型や名前、付随するスタックトレースなど、エラーの詳細についてはわかりません。これに対処し、プロセスを標準化するために、Errorクラスがあります。尚、例外を表示する際にプリミティブ型を使用することは推奨されていません。

Errorクラスを拡張して、独自のエラークラスを作成することができます。その基本的な例は以下の通りです。
```javascript
class ValidationError extends Error {
    constructor(message) {
        super(message);
        this.name = "ValidationError";
    }
}
```
これを、次のように使うことができます。
```javascript
throw ValidationError("Property not found: name")
```
そして `instanceofキーワード` と組み合わせます。
```javascript
try {
    validateForm() // code that throws a ValidationError
} catch (e) {
    if (e instanceof ValidationError) {
        // do something
    } else {
        // do something else
    }
}
```

## エラーの対処方法を知ろう
開発する上で、どのようにエラーを検出し、防止するかを理解しておくことが重要です。

エラーの対処方法については主に3つほどあります
- throw/catch
- onerror()
- callback/promise

各対処方法を解説していき、さいごに選定する基準を紹介させていただきます。

### throw/catch について
他言語と同様に、JavaScript にはエラーの処理に使える機能がいくつもあります。エラー処理について話す前に、throw と　catch するために必要になる機能を理解しておきましょう。

#### throw について
名前からも明らかなように、throw は JavaScript で例外を投げるのに使用します。

number, string、Errorオブジェクト など、何でも throw することができる
しかし、number や string などのプリミティブ型は、エラーに関するデバッグ情報を持たないため、投げるのは効果が高くはないのではないでしょうか。
```javascript
throw TypeError("Please provide a string") 
```

#### try について
コードが例外を投げる可能性があることを示すために使用されます。

```javascript
try {
// 例外を投げるかもしれないコード 
}
```

#### catch について
ブロックをキャッチするのに使用します。つまり、 tryブロック により捕捉されたエラーを処理する役割を果たします。
```javascript
catch (exception) {
// 例外をハンドリングするためのコード 
}
```
そして、 try と catch をあわせて使用すると以下のようになります。
```javascript
try {
// ビジネスロジック 
} catch (exception) {
// エラーハンドリングのコード
}
```
1つの catchブロック の中で if...else文 や switch文 を使って、起こりうるすべてのエラーのパターンを処理することができます。
```javascript
try {
// ビジネスロジック
} catch (exception) {
    if (exception instanceof TypeError) {
        // エラーのタイプが TypeError のときのロジック  
    } else if (exception instanceof RangeError) {
        // エラーのタイプが RangeError のときのロジック  
    }
}
```
#### finally について
finally は、エラー処理後に実行されるコードブロックの定義に使用します。
なので、try →　catch →　finally の順で実行されます。

また、finally は try, catch の結果に関係なく実行されるのです。
以下の場合であっても、クラッシュする前にインタプリタにより finally が実行されます。
- catch がエラーを処理できないとき
- catch でエラーが発生したとき

ちなみに try は、catch や finally　が存在しなと、インタプリタにより`SyntaxError`が返されます。

### onerrorメソッドについて
グローバルにエラーを処理するときに、必要なのは `onerror()メソッド`です。HTML要素で発生するエラーを処理するのに使用できます。
具体例として、`imgタグ` が指定されたURLの画像を見つけられなかった場合、 `onerrorメソッド` を呼び出します。こうすると、ユーザーによるエラーの処理が可能になるのです。

`imgタグ` がフォールバックできるように、 `onerror` で別の画像URLを用意します。
```javascript
let script = document.createElement('script');
script.src = "https://example.com/404.js"; // こんなスクリプトはありません
document.head.append(script);

script.onerror = function() {
    alert("Error loading " + this.src); // Error loading https://example.com/404.js
};
```
具体例としてのグローバルにエラー処理するハンドラ関数
```javascript
window.onerror = (event) => {
    console.log("Error occurred: " + event)
}
```
このハンドラ関数を使用すると、コード内にある複数の try catch を除いた、イベント処理とエラー処理を一元化することができるようになります。
もちろん、単一責任の原則に沿って複数のエラーハンドラを window に関連することもできます。 (特定のハンドラに到達するまで、インタプリタがハンドラを順に追跡するらしいです。)

https://developer.mozilla.org/ja/docs/Web/API/Window/error_event
https://ja.javascript.info/onload-onerror

余談ではありますが、`imgタグ`での[画像読み込みエラー](https://developer.mozilla.org/ja/docs/Web/HTML/Element/Img#%E7%94%BB%E5%83%8F%E8%AA%AD%E3%81%BF%E8%BE%BC%E3%81%BF%E3%82%A8%E3%83%A9%E3%83%BC)で `onerrorメソッド`について解説されてありますが、[ブラウザーの互換性](https://developer.mozilla.org/ja/docs/Web/HTML/Element/Img#%E3%83%96%E3%83%A9%E3%82%A6%E3%82%B6%E3%83%BC%E3%81%AE%E4%BA%92%E6%8F%9B%E6%80%A7) では image の　`onerrorメソッド` を追加するのは非推奨だったりします。（ドキュメントの更新がされてないんでしょうか）

#### コールバックでエラーを渡す
直線的な関数では、シンプルにエラー処理が実行されますが、コールバックを用いることで、その手順を複雑化することができます。

次のようなコードを考えてみましょう。
```javascript
const calculateCube = (number, callback) => {
    setTimeout(() => {
        const cube = number * number * number
        callback(cube)
    }, 1000)
}

const callback = result => console.log(result)

calculateCube(4, callback)
```
上記の関数では、処理に時間を取り、コールバックを利用することで後から結果を返すという非同期の仕組みが作られています。

関数呼び出しの際に4ではなく文字列を入力すると、結果として NaN が返されます。

これに対処する方法が以下の通りです。
```javascript
const calculateCube = (number, callback) => {
    setTimeout(() => {
        if (typeof number !== "number")
            throw new Error("Numeric argument is expected")

        const cube = number * number * number
        callback(cube)
    }, 1000)
}

const callback = result => console.log(result)

try {
    calculateCube(4, callback)
} catch (e) { 
    console.log(e)
}
```
これで理想的には問題が解決するはずです。しかし、関数呼び出しに文字列を渡そうとすると、次のようになります。

関数呼び出し、`try-catchブロック` を実装しているにもかかわらず、エラーが「uncaught」であると表示されます。タイムアウトによる遅延のため、 catchブロック が実行された後にエラーが投げられます。

これは、ネットワーク通話で（予期せぬ遅延が介在し得るため）発生することがあり、このような状況を網羅しながら、アプリを開発する必要があります。

コールバックでエラーを処理する方法は、次の通りです。
```javascript
const calculateCube = (number, callback) => {
    setTimeout(() => {
        if (typeof number !== "number") {
            callback(new TypeError("Numeric argument is expected"))
            return
        }
        const cube = number * number * number
        callback(null, cube)
    }, 2000)
}

const callback = (error, result) => {
    if (error !== null) {
        console.log(error)
        return
    }
    console.log(result)
}

try {
    calculateCube('hey', callback)
} catch (e) {
    console.log(e)
}
```
これで、コンソールの出力は、次のようになります。

これは、エラーが適切に処理されたことを意味します。

#### promise中のエラーの処理
promise は reject されてもプログラミングが終了することはない、という強みがあります。しかし、promise のエラーを処理するために、catch を追加する必要があります。
理解を深めるために、 promise を使用して`calculateCube()メソッド`を追加しましょう。
```javascript
const delay = ms => new Promise(res => setTimeout(res, ms));

const calculateCube = async (number) => {
    if (typeof number !== "number") 
        throw Error("Numeric argument is expected")
    await delay(5000)
    const cube = number * number * number
    return cube
}

try {
    calculateCube(4).then(r => console.log(r))
} catch (e) {
    console.log(e)
}
```
`delay()メソッド`を追加して、4の代わりに文字列を入力しようとすると、出力は以下のようになります。

`promise`の引数に誤りがある場合の`TypeError`の例
ここでも、他のすべての処理が完了した後に promise がエラーを投げることが原因となっています。この問題の解決方法は簡単です。以下のように promiseチェーン に catch() 呼び出しを追加するだけでOKです。
```javascript
calculateCube("hey")
    .then(r => console.log(r))
    .catch(e => console.log(e))
```
これで、出力は以下のようになります。

誤った引数を利用したことによる TypeError の対処例
promiseを用いたエラー処理がいかに簡単であるかをご理解いただけたはずです。さらに、finally()ブロック と promise呼び出しを連鎖させ、エラー処理完了後に実行するコードを追加することもできます。

また、従来型の`try-catch-finally`を用いて、promiseのエラー を処理することもできます。その場合の promise 呼び出しは以下のようになります。
```javascript
try {
    let result = await calculateCube("hey")
    console.log(result)
} catch (e) {
    console.log(e)
} finally {
    console.log('Finally executed")
}
```
これは非同期関数の中でのみ機能します。のエラーを処理する最適解は、promise呼び出しに、catch と finally を連鎖させることです。

状況ごとにエラーの対処方法を使い分けることなるでしょう。上記で解説した throw/catch, onerror(), callback,promiseでの対処方法を選定する基準を紹介させてください。

#### throw/catch を使う状況について 
  - ほとんどの状況で、これを使用することになります。catchブロックの中で、起こりうるすべてのエラーに対する処理を実装するようにしてください。また、tryブロックの後にメモリのクリーンアップを行う必要がある場合は、finallyブロックの記述をお忘れなく。 
  - とは言え、try/catchブロックが多すぎると、コードのメンテナンスが難しくなります。そのような場合は、グローバルハンドラやpromiseメソッドでエラーを処理することをおすすめします。 
  - 非同期try/catchブロックとpromiseのcatch()のどちらを選択するについてですが、非同期try/catchブロックの方が、コードが直線的になり、デバッグしやすいので、そちらを推奨します。

#### onerror() を使う状況について
  - onerror() メソッドは、アプリケーションで多くのエラーを処理する必要があり、 しかも問題の箇所がコードベース全体に散らばっていることが分かっている場合に有用です。Onerror()を使用すると、エラーをアプリケーション内のイベントのように扱うことができます。複数のエラーハンドラを定義して、最初のレンダリング時にアプリのwindowに紐付けることが可能です。 
  - 小規模なプロジェクトでは、エラーの範囲が狭いため onerror()メソッド の設定が不必要に難しくなることがありますのでご注意ください。対象のアプリにあまり多くのエラーがないことを確信しているなら、より基本的なthrow/catchを使う方がいいでしょう。

#### callbackとpromise を使う状況について
  - コールバックとpromiseのエラー処理は、その設計や構造から異なります。コードを書く前にこの2つのどちらかを選ぶのであれば、promiseを選ぶのが賢明です。 
  - というのも、promiseにはcatch()とfinally()ブロックを連鎖させてエラーを簡単に処理する仕組みが組み込まれています。この方法は、エラーを処理するために引数を定義したり、既存の引数を再利用したりするよりも簡単でクリーンです。

コードベース内のミスでエラーが発生することは、必ず直面します。開発中やデバッグ中に、不必要な変更を加えてしまい、それが原因で新たなエラーが発生することすらあります。変更を加えるたびに自動でのテストを実行しておく方法もあるでしょう。ただし、これにより分かるのは、問題があるかないかという実行結果だけです。コードレビューでもエラーを取り除けるようにしたいですね。

## エラーを解決しよう！
エラー解決の効果を最大化するためには、実装の際にいくつかの点に留意したいところです。具体的なヒントを以下にまとめました。 

### 操作上の例外処理に独自のエラータイプを使用する
   記事の前半で独自のエラータイプの作成方法をご紹介しました。これは、アプリケーション固有の状況に合わせてエラー処理のしかたを調整できるようになるためです。一般的な Error クラスではなく、可能な限り独自のエラータイプを使用することをお勧めします。そうすることで、通常よりも多くの情報や背景が確認できるようになります。

さらに、独自のエラータイプでは、呼び出し側の環境におけるエラーの表示方法を調整することができます。つまり、特定の項目を隠したり、エラーに関するもっと詳しい情報を表示したりできます。

エラーの内容を好きなようにフォーマットすることも可能です。エラーの解釈や処理のしかたを細かく制御することができます。

### 例外を放置しない
   上級開発者であっても、コードの奥深くで例外をほったらかしにしてしまう、という初歩的なミスを犯すことがよくあります。

例えば、こんな状況です。実行が任意であるコードがあったとします。もしそれが機能すれば、素晴らしいことです。一方でもし機能しなくても、大した問題はありません。

このような場合、このコードをtryブロックに入れ、空のcatchブロックでその場しのぎをしたくなるかもしれません。しかし、そうすることで、そのコードがあらゆる種類のエラーを引き起こす可能性があります。これは、コードベースが大きくなった時、そして、このようなエラー管理の不備が多い場合、大きなリスクとなります。

例外を処理する上でのベストプラクティスはこうです。すべての例外を処理するレベルを決定し、そこに至るまでに、例外処理にとばすこと。このレベルは、コントローラ（MVCアーキテクチャのアプリの場合）でもミドルウェア（従来のサーバー指向のアプリの場合）でもかまいません。

こうすることで、アプリで発生しているすべてのエラーの場所を把握しながら対処法（たとえ何もしないことを選ぼうとも）を賢く選択できるようになります。

### ログとエラーアラートを一元化する
   エラーの処理における大事な要素として、ログを取ることが挙げられます。エラーのログを一元的に管理しないと、アプリの使用状況に関する貴重な情報を見逃してしまう可能性があります。

アプリのイベントログを確認することで、エラーに関する重要なデータを把握し、素早いデバッグに役立てることができます。アプリに適切なアラートメカニズムを設定しておいて、エラーが発生したときに、それが多くのユーザーに影響を及ぼす前に把握するのが理想です。

デフォルトのロガーを使用するか、好みにあわせてロガーを作成することをお勧めします。ロガーの中には、エラーのレベル (警告、デバッグ、情報など) に応じて処理方法を設定でき、中にはログをすぐにリモートロギングのサーバーに送信するものさえあります。このようにして、アプリケーションのロジックが利用者に対してどのように実行されるかを監視できます。

### ユーザーに対し適切にエラーを通知する
   エラー処理方法を定義する際に、ユーザーを念頭に置く必要があります。

アプリの正常な機能を妨げるすべての問題は、目に見えるかたちで（アラートやエラーメッセージで）確認できるようにしましょう。これにより、ユーザーによる解決策の実施が促せます。操作の再試行やログアウトと再ログインなど、エラーの簡単な解決方法を知っている場合は、アラートに必ず記載しましょう。

日常的な使用に支障をきたさないエラーの場合、アラートは出さずに、後で解決できるように、リモートサーバーで記録することも可能です。

### ミドルウェアの実装（Node.js）
   Node.js環境はサーバーアプリケーションに機能を追加するミドルウェアをサポートしています。この機能を利用して、サーバーのエラー処理用ミドルウェアを作成することができます。

ミドルウェアを使用する最も大きな利点は、すべてのエラーを一箇所で集中的に処理できること。この設定は、テスト用に簡単に有効/無効化できます。

基本的なミドルウェアの作り方を説明します。
```javascript
export const logError = err => {
    console.log("ERROR: " + String(err))
}

export const errorLoggerMiddleware = (err, req, res, next) => {
    logError(err)
    next(err)
}

export const returnErrorMiddleware = (err, req, res, next) => {
    res.status(err.statusCode || 500)
        .send(err.message)
}
```
そして、このミドルウェアをアプリ内で次のように使用することができます。
```javascript
import { errorLoggerMiddleware, returnErrorMiddleware } from "./middleware"

app.use(errorLoggerMiddleware)

app.use(returnErrorMiddleware)
```
これで、ミドルウェアの内部で独自のロジックを定義し、適切にエラーを処理できます。もう、コードベース全体で、個別のエラー処理構造の実装に頭を悩ませる必要はありません。

#### 意図的にアプリを再起動する (Node.js)
   Node.jsアプリがエラーに遭遇した際、必ずしも例外を投げるとは限らず、アプリを終了しようとする場合があります。このようなエラーとして、CPUの大量消費、メモリの肥大化、メモリリークなど、プログラミングのミスに起因する問題が挙げられます。これが発生した場合には、Node.jsのクラスタモードや、PM2のようなツールを使ってアプリをクラッシュさせ、再起動（グレースフル・リスタート）させるのが理想です。これにより、ユーザーの操作によってアプリがクラッシュしてユーザー体験が害されるのを回避できます。

#### 「uncaught」の例外を全て「catch」する (Node.js)
   プログラミングを徹底しようとも、アプリで発生する可能性のあるすべてのエラーをカバーできているとは限りません。したがって、アプリで発生する「捕捉から漏れた」例外をすべてcatchするフォールバック戦略を実装することが肝要です。

その方法をご紹介します。
```javascript
process.on('uncaughtException', error => {
console.log("ERROR: " + String(error))
// other handling mechanisms
})
```
また、発生したエラーが標準的な例外なのか、特別な操作エラーなのかを識別することもできます。その結果に基づいて、プロセスを終了し、再起動することで、予期せぬ動作を回避することが可能です。

#### 未処理の「reject」をすべて「catch」する（Node.js）
   例外をすべてカバーすることができないのと同様に、promiseのrejectをすべて処理しきれない可能性もあります。しかし、例外とは異なり、promiseのrejectはエラーを投げません。

そのため、重要なpromiseがrejectになった場合、それが最終的には、予期せぬ動作につながるリスクがあります。そのため、promiseのrejectを処理するフォールバックの仕組みを実装することが非常に重要です。

その方法が、以下の通りです。
```javascript
const promiseRejectionCallback = error => {
    console.log("PROMISE REJECTED: " + String(error))
}

process.on('unhandledRejection', callback)
```
## さいごに
エラーは自然なものです。場合によっては、ユーザーへの反応として、意図的にエラーを投げる必要があることさえあります。したがって、エラーの構造と種類を理解することは非常に重要です。
さらに、アプリケーションを停止させてしまうエラーを特定し、それを防ぐための知識と道具を用意しておく必要があります。

間違った知識や内容がありましたら、ご指摘ください。